Workbook

Sheet Nur - VIII DPS
A1: DELHI PUBLIC SCHOOL, 0.5KM MILESTONE, JIND ROAD, ROHTAK
A2: SUMMER TIME TABLE 3.0 (Session2023-24)
A3: w.e.f - 04.07.2023 [Tuesday]
A5: CLASS | B5: WEEKDAYS | C5: Recreation | D5: I | E5: II | F5: III | G5: 0.44791667 | H5: IV | I5: V | J5: VI | K5: VII | L5: INCHARGE
C6: 08:00 - 08:45 | D6: 08:45 - 09:25 | E6: 09:25 - 10:05 | F6: 10:05 - 10:45 | G6: 0.45833333 | H6: 11:00 - 11:40 | I6: 11:40 - 12:20 | J6: 12:20 - 01:00 | K6: 01:00 - 01:40
B7: DURATION | C7: 45 Minutes | D7: 40 Minutes | E7: 40 Minutes | F7: 40 Minutes | G7: 15Min | H7: 40 Minutes | I7: 40 Minutes | J7: 40 Minutes | K7: 40 Minutes
A8: NUR - I | B8: MONDAY | C8: SWIMMING 1-2 INDU | D8: MATHS 1-6 INDU | E8: HINDI 1-6 INDU | F8: ART 1-6 SHOBHA | G8: L U N C H | H8: E V S 1-6 SARITA | I8: ENGLISH 1-6 SARITA | J8: ACTIVITY 1-6 SANJAY | K8: MUSIC 1-6 APARNA | L8: INDU
B9: TUESDAY
B10: WEDNESDAY | C10: HOBBY 3
B11: THURSDAY | C11: SPORTS 4-5 INDU
B12: FRIDAY
B13: SATURDAY | C13: ASSEMBLY 6
A14: II | B14: MONDAY | C14: SWIMMING 1-2 SARITA | D14: E V S 1-6 SARITA | E14: MATHS 1-6 RENUKA | F14: HINDI 1-6 SARITA | G14: L U N C H | H14: ENGLISH 1-6 RENUKA | I14: GK 1-2 ANJU | L14: SARITA
B15: TUESDAY
B16: WEDNESDAY | C16: HOBBY 3 | I16: ART 3-4 SHOBHA
B17: THURSDAY | C17: SPORTS 4-5 SARITA
B18: FRIDAY | I18: I T 5-6 ASHA
B19: SATURDAY | C19: ASSEMBLY 6
A21: III | B21: MONDAY | C21: SWIMMING 1-2 SHOBHA | D21: E V S 1-6 SHOBHA | E21: ART 1-3 SHOBHA | F21: GK 1-3 ANJU | G21: L U N C H | H21: HINDI 1-6 ANJU | I21: MATHS 1-6 MANJU | J21: ENGLISH 1-6 SARITA | K21: MUSIC 1-6 APARNA | L21: SHOBHA
B22: TUESDAY
B23: WEDNESDAY | C23: HOBBY 3
B24: THURSDAY | C24: SPORTS 4-5 SANJAY | E24: LIBRARY 4-6 KUSUM | F24: I T 4-6 ASHA
B25: FRIDAY
B26: SATURDAY | C26: ASSEMBLY 6
A27: IV | B27: MONDAY | C27: SWIMMING 1-2 ANJU | D27: HINDI 1-6 ANJU | E27: ART 1-2 SHOBHA | F27: GK 1-3 ANJU | G27: L U N C H | H27: S S T 1-6 INDU | I27: ENGLISH 1-6 ANURADHA | J27: SCIENCE 1-6 ANJALI | K27: MATHS 1-6 MANJU | L27: ANJU
B28: TUESDAY
B29: WEDNESDAY | C29: HOBBY 3 | E29: LIBRARY 3-4 KUSUM
B30: THURSDAY | C30: SPORTS 4-5 SANJAY | F30: I T 4-6 ASHA
B31: FRIDAY | E31: MUSIC 5-6 APARNA
B32: SATURDAY | C32: ASSEMBLY 6
A33: V | B33: MONDAY | C33: SWIMMING 1-2 ASHA | D33: ENGLISH 1-6 ANUJ | E33: ART 1-2 SHOBHA | F33: HINDI 1-6 KAMLESH | G33: L U N C H | H33: MATHS 1-6 MANJU | I33: I T 1-3 ASHA | J33: S S T 1-6 INDU | K33: SCIENCE 1-6 ANJALI | L33: ASHA
B34: TUESDAY
B35: WEDNESDAY | C35: HOBBY 3 | E35: LIBRARY 3-4 KUSUM
B36: THURSDAY | C36: SPORTS 4-5 SANJAY | I36: GK 4-6 KAMLESH
B37: FRIDAY | E37: MUSIC 5-6 APARNA
B38: SATURDAY | C38: ASSEMBLY 6
A40: VI | B40: MONDAY | C40: SWIMMING 1-2 KAMLESH | D40: HINDI 1-6 KAMLESH | E40: SKT 1-3 ANJU | F40: MATHS 1-6 MANJU | G40: L U N C H | H40: ENGLISH 1-6 ANUJ | I40: SCIENCE 1-6 ANJALI | J40: IT 1-2 ASHA | K40: S S T 1-6 INDU | L40: KAMLESH
B41: TUESDAY
B42: WEDNESDAY | C42: HOBBY 3 | J42: GK 3-4 RENUKA
B43: THURSDAY | C43: SPORTS 4-5 SANJAY | E43: MUSIC 4 APARNA
...

Sheet All
B1: INTERNATIONAL BHARTI SCHOOL, 5KM MILESTONE, GOHANA ROAD, ROHTAK
B2: SUMMER TIME TABLE 3.0 (Session 2025-26)
B3: w.e.f - 01.07.2025 (Tuesday)
B5: CLASS | C5: PERIOD / WEEKDAYS | E5: ZERO | F5: I | G5: II | H5: III | I5: IV | J5: 0.44791667 | K5: V | L5: VI | M5: VII | N5: VIII | O5: INCHARGE
E6: 07:45 - 08:05 | F6: 08:05 - 08:45 | G6: 08:45 - 09:25 | H6: 09:25 - 10:05 | I6: 10:05 - 10:45 | J6: 0.46180556 | K6: 11:05 - 11:45 | L6: 11:45 - 12:25 | M6: 12:25 - 01:05 | N6: 01:05 - 01:35
C7: DURATION | E7: 08:00 - 08:20 | F7: 08:20 - 09:00 | G7: 09:00 - 09:40 | H7: 09:40 - 10:20 | I7: 10:20 - 11:00 | J7: 0.47222222 | K7: 11:20 - 12:00 | L7: 12:00 - 12:40 | M7: 12:40 - 01:20 | N7: 01:20 - 02:00
E8: 20 Minutes | F8: 40 Minutes | G8: 40 Minutes | H8: 40 Minutes | I8: 40 Minutes | J8: 20Min | K8: 40 Minutes | L8: 40 Minutes | M8: 40 Minutes | N8: 40 Minutes
B9: IV Rose | C9: 1 | D9: MONDAY | E9: Class Incharge Attendance / Activity | F9: ENGLISH 1-6 SHAKTI | G9: SPORTS 1-3 PARVEEN / JYOTI / PRIYANKA | H9: S S T 1-6 MANISHA | I9: SCIENCE 1-6 NISHA | J9: L U N C H | K9: HINDI 1-6 PINKI | L9: MATHS 1-6 MALTI | M9: MUSIC/DANCE 1-2 JASMINE | N9: M A 1-2 POOJA S | O9: SHAKTI SS ENGLISH
C10: 2 | D10: TUESDAY
C11: 3 | D11: WEDNESDAY | M11: COMMUNICATION 3-5 SHAKTI | N11: ART 3 LAKSHITA
C12: 4 | D12: THURSDAY | G12: I T 4-6 SANGEETA | N12: AI 4 SUMIT
C13: 5 | D13: FRIDAY | N13: LIBRARY 5 AJMER
C14: 6 | D14: SATURDAY | M14: HOUSE ACTIVITY 6 INCHARGE
B15: IV Lily | C15: 1 | D15: MONDAY | E15: =E9 -> Class Incharge Attendance / Activity | F15: S S T 1-6 MANISHA | G15: =G9 -> SPORTS 1-3 PARVEEN / JYOTI / PRIYANKA | H15: SCIENCE 1-6 NISHA | I15: ENGLISH 1-6 ETISHA | J15: L U N C H | K15: MATHS 1-6 POOJA S | L15: HINDI 1-6 PINKI | M15: I T 1-3 SANGEETA | N15: AI 1 SUMIT | O15: MANISHA MN S Sci
C16: 2 | D16: TUESDAY | N16: ART 2 LAKSHITA
C17: 3 | D17: WEDNESDAY | N17: LIBRARY 3 AJMER
C18: 4 | D18: THURSDAY | G18: COMM 4-6 SHAKTI | M18: M A 4-5 POOJA S | N18: MUSIC/DANCE 4-5 JASMINE
C19: 5 | D19: FRIDAY
C20: 6 | D20: SATURDAY | M20: HOUSE ACTIVITY 6 INCHARGE
B21: IV Lotus | C21: 1 | D21: MONDAY | E21: =E15 -> Class Incharge Attendance / Activity | F21: SCIENCE 1-6 NISHA | G21: =G15 -> SPORTS 1-3 PARVEEN / JYOTI / PRIYANKA | H21: HINDI 1-6 PINKI | I21: MATHS 1-6 MALTI | J21: L U N C H | K21: ENGLISH 1-6 SHAKTI | L21: S S T 1-6 MANISHA | M21: ART 1 LAKSHITA | N21: I T 1-3 SANGEETA | O21: NISHA NT SCIENCE
C22: 2 | D22: TUESDAY | M22: AI 2 SUMIT
C23: 3 | D23: WEDNESDAY | M23: LIBRARY 3 AJMER
C24: 4 | D24: THURSDAY | G24: COMM 4-6 ETISHA | M24: MUSIC/DANCE 4-5 JASMINE | N24: M A 4-5 POOJA S
C25: 5 | D25: FRIDAY
C26: 6 | D26: SATURDAY | M26: HOUSE ACTIVITY 6 INCHARGE
B28: CLASS | C28: PERIOD / WEEKDAYS | E28: ZERO | F28: I | G28: II | H28: III | I28: IV | J28: 0.44791667 | K28: V | L28: VI | M28: VII | N28: VIII | O28: INCHARGE
E29: 07:45 - 08:05 | F29: 08:05 - 08:45 | G29: 08:45 - 09:25 | H29: 09:25 - 10:05 | I29: 10:05 - 10:45 | J29: 0.46180556 | K29: 11:05 - 11:45 | L29: 11:45 - 12:25 | M29: 12:25 - 01:05 | N29: 01:05 - 01:35
C30: DURATION | E30: 08:00 - 08:20 | F30: 08:20 - 09:00 | G30: 09:00 - 09:40 | H30: 09:40 - 10:20 | I30: 10:20 - 11:00 | J30: 0.47222222 | K30: 11:20 - 12:00 | L30: 12:00 - 12:40 | M30: 12:40 - 01:20 | N30: 01:20 - 02:00
E31: 20 Minutes | F31: 40 Minutes | G31: 40 Minutes | H31: 40 Minutes | I31: 40 Minutes | J31: 20Min | K31: 40 Minutes | L31: 40 Minutes | M31: 40 Minutes | N31: 40 Minutes
B32: V Rose | C32: 1 | D32: MONDAY | E32: =E21 -> Class Incharge Attendance / Activity | F32: MATHS 1-6 MALTI | G32: HINDI 1-6 PINKI | H32: I T 1-2 SANGEETA | I32: S S T 1-6 MANISHA | J32: L U N C H | K32: SCIENCE 1-6 NISHA | L32: ENGLISH 1-6 ETISHA | M32: M A 1-2 POOJA S | N32: MUSIC/DANCE 1-2 JASMINE | O32: MALTI MS MATHS
C33: 2 | D33: TUESDAY
C34: 3 | D34: WEDNESDAY | H34: COMM. 3-4 ETISHA | M34: AI 3 SUMIT | N34: FRENCH 3 M
C35: 4 | D35: THURSDAY | M35: ART 4 LAKSHITA | N35: COMM 4 SEEMA
C36: 5 | D36: FRIDAY | H36: SPORTS 5-6 PA / JY / PR | M36: LIBRARY 5 AJMER | N36: COMM 5 ETISHA
C37: 6 | D37: SATURDAY | M37: HOUSE ACTIVITY 6 INCHARGE FRENCH 6
B38: V Lily | C38: 1 | D38: MONDAY | E38: =E32 -> Class Incharge Attendance / Activity | F38: ENGLISH 1-6 ETISHA | G38: S S T 1-6 MANISHA | H38: MUSIC/DANCE 1-2 JASMINE | I38: HINDI 1-6 PINKI | J38: L U N C H | K38: MATHS 1-6 MALTI | L38: SCIENCE 1-6 NISHA | M38: AI 1 SUMIT | N38: COMM 1-3 SEEMA | O38: ETISHA ET ENGLISH
C39: 2 | D39: TUESDAY | M39: LIBRARY 2 AJMER
C40: 3 | D40: WEDNESDAY | H40: M A 3-4 POOJA S | M40: ART 3 LAKSHITA
C41: 4 | D41: THURSDAY | M41: I T 4-5 SANGEETA | N41: FRENCH 4-5 MEENAKSHI
C42: 5 | D42: FRIDAY | H42: SPORTS 5-6 PA / JY / PR
...

Sheet 4-5
B1: INTERNATIONAL BHARTI SCHOOL, 5KM MILESTONE, GOHANA ROAD, ROHTAK
B2: SUMMER TIME TABLE 3.3 (Session 2025-26)
B3: w.e.f - 10.07.2025 (Thursday)
B5: CLASS | C5: PERIOD / DAY/ DURATION | E5: ZERO | F5: I | G5: II | H5: III | I5: IV | J5: 0.45833333 | K5: V | L5: VI | M5: VII | N5: VIII | O5: INCHARGE
E6: 08:00 - 08:20 | F6: 08:20 - 09:00 | G6: 09:00 - 09:40 | H6: 09:40 - 10:20 | I6: 10:20 - 11:00 | J6: 0.47222222 | K6: 11:20 - 12:00 | L6: 12:00 - 12:40 | M6: 12:40 - 01:20 | N6: 01:20 - 02:00
E7: 20 Minutes | F7: 40 Minutes | G7: 40 Minutes | H7: 40 Minutes | I7: 40 Minutes | J7: 20Min | K7: 40 Minutes | L7: 40 Minutes | M7: 40 Minutes | N7: 40 Minutes
B8: IV Rose | C8: 1 | D8: MONDAY | E8: Attendance / Activity CLASS INCHARGE | F8: ENGLISH 1-6 SNEHLATA | G8: SPORTS 1-3 PRIYANKA | H8: HINDI 1-6 PINKI | I8: SCIENCE 1-6 NISHA | J8: L U N C H | K8: S S T 1-6 MANISHA | L8: MATHS 1-6 MALTI | M8: MUSIC/DANCE 1-2 SONAM | N8: M A 1-2 POOJA S | O8: SNEHLATA SL ENGLISH
C9: 2 | D9: TUESDAY
C10: 3 | D10: WEDNESDAY | M10: COMMUNICATION 3-5 SNEHLATA | N10: ARTS 3 LAKSHITA
C11: 4 | D11: THURSDAY | G11: I T 4-6 SANGEETA | N11: AI 4 SUMIT
C12: 5 | D12: FRIDAY | N12: LIBRARY 5 KIRTI
C13: 6 | D13: SATURDAY | M13: HOUSE ACTIVITY 6 INCHARGE
B14: IV Lily | C14: 1 | D14: MONDAY | E14: =E8 -> Attendance / Activity CLASS INCHARGE | F14: S S T 1-6 MANISHA | G14: SPORTS 1-3 PARVEEN | H14: SCIENCE 1-6 NISHA | I14: ENGLISH 1-6 ETISHA | J14: L U N C H | K14: MATHS 1-6 POOJA S | L14: HINDI 1-6 PINKI | M14: I T 1-3 SANGEETA | N14: AI 1 SUMIT | O14: MANISHA MA S Sci
C15: 2 | D15: TUESDAY | N15: ARTS 2 LAKSHITA
C16: 3 | D16: WEDNESDAY | N16: LIBRARY 3 KIRTI
C17: 4 | D17: THURSDAY | G17: COMM 4-6 SNEHLATA | M17: M A 4-5 POOJA S | N17: MUSIC/DANCE 4-5 SONAM
C18: 5 | D18: FRIDAY
C19: 6 | D19: SATURDAY | M19: HOUSE ACTIVITY 6 INCHARGE
B20: IV Lotus | C20: 1 | D20: MONDAY | E20: =E14 -> Attendance / Activity CLASS INCHARGE | F20: SCIENCE 1-6 NISHA | G20: SPORTS 1-3 JYOTI | H20: MATHS 1-6 POOJA S | I20: ENGLISH 1-6 SNEHLATA | J20: L U N C H | K20: HINDI 1-6 PINKI | L20: S S T 1-6 MANISHA | M20: ARTS 1 LAKSHITA | N20: I T 1-3 SANGEETA | O20: NISHA NT SCIENCE
C21: 2 | D21: TUESDAY | M21: AI 2 SUMIT
C22: 3 | D22: WEDNESDAY | M22: LIBRARY 3 KIRTI
C23: 4 | D23: THURSDAY | G23: COMM 4-6 ETISHA | M23: MUSIC/DANCE 4-5 SONAM | N23: M A 4-5 POOJA S
C24: 5 | D24: FRIDAY
C25: 6 | D25: SATURDAY | M25: HOUSE ACTIVITY 6 INCHARGE
B27: CLASS | C27: PERIOD / WEEKDAYS | E27: ZERO | F27: I | G27: II | H27: III | I27: IV | J27: 0.44791667 | K27: V | L27: VI | M27: VII | N27: VIII | O27: INCHARGE
E28: 07:45 - 08:05 | F28: 08:05 - 08:45 | G28: 08:45 - 09:25 | H28: 09:25 - 10:05 | I28: 10:05 - 10:45 | J28: 0.46180556 | K28: 11:05 - 11:45 | L28: 11:45 - 12:25 | M28: 12:25 - 01:05 | N28: 01:05 - 01:35
C29: DURATION | E29: 08:00 - 08:20 | F29: 08:20 - 09:00 | G29: 09:00 - 09:40 | H29: 09:40 - 10:20 | I29: 10:20 - 11:00 | J29: 0.47222222 | K29: 11:20 - 12:00 | L29: 12:00 - 12:40 | M29: 12:40 - 01:20 | N29: 01:20 - 02:00
E30: 20 Minutes | F30: 40 Minutes | G30: 40 Minutes | H30: 40 Minutes | I30: 40 Minutes | J30: 20Min | K30: 40 Minutes | L30: 40 Minutes | M30: 40 Minutes | N30: 40 Minutes
B32: V Rose | C32: 1 | D32: MONDAY | E32: =E20 -> Attendance / Activity CLASS INCHARGE | F32: MATHS 1-6 MALTI | G32: FRENCH 1-2 MEENAKSHI | H32: COMM. 1-2 ETISHA | I32: S S T 1-6 SEEMA | J32: L U N C H | K32: SCIENCE 1-6 NISHA | L32: ENGLISH 1-6 ETISHA | M32: M A 1-2 POOJA S | N32: MUSIC/DANCE 1-2 SONAM | O32: MALTI MS MATHS
C33: 2 | D33: TUESDAY
C34: 3 | D34: WEDNESDAY | G34: COMM. 3 ETISHA | H34: I T 3-4 SANGEETA | M34: AI 3 SUMIT | N34: HINDI 3-5 PINKI
C35: 4 | D35: THURSDAY | G35: HINDI 4-6 POOJA | M35: ARTS 4 LAKSHITA
C36: 5 | D36: FRIDAY | H36: SPORTS 5-6 PRIYANKA | M36: LIBRARY 5 KIRTI
C37: 6 | D37: SATURDAY | M37: HOUSE ACTIVITY 6 INCHARGE
B38: V Lily | C38: 1 | D38: MONDAY | E38: =E32 -> Attendance / Activity CLASS INCHARGE | F38: ENGLISH 1-6 ETISHA | G38: S S T 1-6 MANISHA | H38: MUSIC/DANCE 1-2 SONAM | I38: HINDI 1-6 PINKI | J38: L U N C H | K38: MATHS 1-6 MALTI | L38: SCIENCE 1-6 NISHA | M38: AI 1 SUMIT | N38: COMM 1-3 SEEMA | O38: ETISHA ET ENGLISH
C39: 2 | D39: TUESDAY | M39: LIBRARY 2 KIRTI
C40: 3 | D40: WEDNESDAY | H40: M A 3-4 MALTI | M40: ARTS 3 LAKSHITA
C41: 4 | D41: THURSDAY | M41: I T 4-5 SANGEETA | N41: FRENCH 4-5 MEENAKSHI
C42: 5 | D42: FRIDAY | H42: SPORTS 5-6 PARVEEN
C43: 6 | D43: SATURDAY | M43: HOUSE ACTIVITY 6 INCHARGE
...

Sheet 6
B1: INTERNATIONAL BHARTI SCHOOL, 5KM MILESTONE, GOHANA ROAD, ROHTAK
B2: ='4-5'!B2:O2 -> SUMMER TIME TABLE 3.3 (Session 2025-26)
B3: ='4-5'!B3:O3 -> w.e.f - 10.07.2025 (Thursday)
B5: CLASS | C5: PERIOD / DAY/ DURATION | E5: ZERO | F5: I | G5: II | H5: III | I5: IV | J5: 0.45833333 | K5: V | L5: VI | M5: VII | N5: VIII | O5: INCHARGE
E6: 08:00 - 08:20 | F6: 08:20 - 09:00 | G6: 09:00 - 09:40 | H6: 09:40 - 10:20 | I6: 10:20 - 11:00 | J6: 0.47222222 | K6: 11:20 - 12:00 | L6: 12:00 - 12:40 | M6: 12:40 - 01:20 | N6: 01:20 - 02:00
E7: 20 Minutes | F7: 40 Minutes | G7: 40 Minutes | H7: 40 Minutes | I7: 40 Minutes | J7: 20Min | K7: 40 Minutes | L7: 40 Minutes | M7: 40 Minutes | N7: 40 Minutes
B8: VI Rose | C8: 1 | D8: MONDAY | E8: Attendance / Activity CLASS INCHARGE | F8: HINDI 1-3 POOJA | G8: HINDI 1-3 POOJA | H8: SCIENCE 1-6 SEEMA | I8: I T 1-3 SANGEETA | J8: L U N C H | K8: S S T 1-6 NISHA GILL | L8: MATHS 1-6 POOJA S | M8: ENGLISH 1-6 NIDHI | N8: M A 1-2 PREETI | O8: POOJA PN HINDI
C9: 2 | D9: TUESDAY
C10: 3 | D10: WEDNESDAY | N10: COMM. 3-5 ETISHA
C11: 4 | D11: THURSDAY | F11: FRENCH / SKT 4-6 MN / RAJNI | G11: ARTS 4 LAKSHITA | I11: MUSIC/DANCE 4
C12: 5 | D12: FRIDAY | G12: SPORTS 5-6 PRIYANKA | I12: AI 5 SUMIT
C13: 6 | D13: SATURDAY | I13: LIBRARY 6 KIRTI | N13: H A 6 INCHARGE
B14: VI Lily | C14: 1 | D14: MONDAY | E14: =E8 -> Attendance / Activity CLASS INCHARGE | F14: MATHS 1-6 POOJA S | G14: SCIENCE 1-6 PRIYA | H14: SPORTS 1 PRIYANKA | I14: AI 1 SUMIT | J14: L U N C H | K14: ENGLISH 1-6 SNEHLATA | L14: S S T 1-6 NISHA GILL | M14: HINDI 1-3 POOJA | N14: MUSIC/DANCE 1 | O14: POOJA PS MATHS
C15: 2 | D15: TUESDAY | H15: SPORTS 2 PARVEEN | I15: LIBRARY 2 KIRTI | N15: COMM. 2-3 SONAL
C16: 3 | D16: WEDNESDAY | H16: ARTS 3 LAKSHITA | I16: COMM 3 SONAL
C17: 4 | D17: THURSDAY | H17: HINDI 4-6 POOJA | I17: I T 4-6 SANGEETA | M17: FRENCH / SKT 1-3 MN / RAJNI | N17: M A 4-5 PREETI
C18: 5 | D18: FRIDAY
C19: 6 | D19: SATURDAY | N19: H A 6 INCHARGE
B20: VI Lotus | C20: 1 | D20: MONDAY | E20: =E14 -> Attendance / Activity CLASS INCHARGE | F20: S S T 1-6 NISHA GILL | G20: SCIENCE 1-6 SEEMA | H20: FRENCH / SKT 1-3 MN / RAJNI | I20: ENGLISH 1-6 SHAKTI | J20: L U N C H | K20: SPORTS 1-2 PARVEEN | L20: HINDI 1-6 POOJA | M20: MATHS 1-6 MALTI | N20: M A 1-2 NISHU | O20: NISHA G NG S Sci
C21: 2 | D21: TUESDAY
C22: 3 | D22: WEDNESDAY | K22: LIBRARY 3 KIRTI | N22: MUSIC/DANCE 3
C23: 4 | D23: THURSDAY | H23: COMM. 4-6 SONAL | K23: I T 4-6 SANGEETA | N23: ARTS 4 LAKSHITA
C24: 5 | D24: FRIDAY | N24: AI 5 SUMIT
C25: 6 | D25: SATURDAY | N25: H A 6 INCHARGE
B26: VI Tulip | C26: 1 | D26: MONDAY | E26: =E20 -> Attendance / Activity CLASS INCHARGE | F26: I T 1-3 SANGEETA | G26: MATHS 1-6 MALTI | H26: COMM. 1-3 SONAL | I26: SCIENCE 1-6 PRIYA | J26: L U N C H | K26: SPORTS 1-2 PRIYANKA | L26: M A 1-2 PREETI | M26: S S T 1-6 NISHA GILL | N26: ENGLISH 1-2 ETISHA | O26: SANGEETA SA COMP
C27: 2 | D27: TUESDAY
C28: 3 | D28: WEDNESDAY | K28: ENGLISH 3-6 ETISHA | L28: AI 3 SUMIT | N28: HINDI 3-5 POOJA
C29: 4 | D29: THURSDAY | F29: HINDI 4-6 POOJA | H29: FRENCH / SKT 4-6 MN / RAJNI | L29: MUSIC/DANCE 4
C30: 5 | D30: FRIDAY | L30: ARTS 5 LAKSHITA
C31: 6 | D31: SATURDAY | L31: LIBRARY 6 KIRTI | N31: H A 6 INCHARGE

Sheet 7-8
B1: INTERNATIONAL BHARTI SCHOOL, 5KM MILESTONE, GOHANA ROAD, ROHTAK
B2: ='6'!B2:O2 -> SUMMER TIME TABLE 3.3 (Session 2025-26)
B3: ='6'!B3:O3 -> w.e.f - 10.07.2025 (Thursday)
B5: CLASS | C5: PERIOD / DAY/ DURATION | E5: ZERO | F5: I | G5: II | H5: III | I5: IV | J5: 0.45833333 | K5: V | L5: VI | M5: VII | N5: VIII | O5: INCHARGE
E6: 08:00 - 08:20 | F6: 08:20 - 09:00 | G6: 09:00 - 09:40 | H6: 09:40 - 10:20 | I6: 10:20 - 11:00 | J6: 0.47222222 | K6: 11:20 - 12:00 | L6: 12:00 - 12:40 | M6: 12:40 - 01:20 | N6: 01:20 - 02:00
E7: 20 Minutes | F7: 40 Minutes | G7: 40 Minutes | H7: 40 Minutes | I7: 40 Minutes | J7: 20Min | K7: 40 Minutes | L7: 40 Minutes | M7: 40 Minutes | N7: 40 Minutes
B8: VII Rose | C8: 1 | D8: MONDAY | E8: Attendance / Activity CLASS INCHARGE | F8: I T 1-3 SUMIT | G8: S S T 1-4 NISHA GILL | H8: MATHS 1-6 PREETI | I8: FRENCH / SKT 1-3 MN / RAJNI | J8: L U N C H | K8: ENGLISH 1-6 SHAKTI | L8: SCIENCE 1-6 KUSUM RATHI | M8: M A 1-2 SHARMILA | N8: HINDI 1-3 SARITA | O8: SARITA SR HINDI
C9: 2 | D9: TUESDAY
C10: 3 | D10: WEDNESDAY | M10: MUSIC/DANCE 3
C11: 4 | D11: THURSDAY | F11: HINDI 4-6 SARITA | I11: COMM. 4-6 SONAL | M11: LIBRARY 4 KIRTI | N11: S S T 4-5 NISHA GILL
C12: 5 | D12: FRIDAY | G12: SPORTS 5-6 JYOTI | M12: AI 5 SUMIT
C13: 6 | D13: SATURDAY | M13: ARTS 6 LAKSHITA | N13: H A 6 INCHARGE
B14: VII Lily | C14: 1 | D14: MONDAY | E14: =E8 -> Attendance / Activity CLASS INCHARGE | F14: MATHS 1-6 PREETI | G14: COMM. 1-3 SONAL | H14: HINDI 1-2 POOJA | I14: I T 1-3 REENA | J14: L U N C H | K14: SCIENCE 1-6 KUSUM RATHI | L14: ENGLISH 1-6 NIDHI | M14: S SCI 1-6 SAVITA | N14: SPORTS 1 JYOTI | O14: PREETI PT MATHS
C15: 2 | D15: TUESDAY | N15: LIBRARY 2 KIRTI
C16: 3 | D16: WEDNESDAY | H16: HINDI 3-6 SARITA | N16: SPORTS 3 JYOTI
C17: 4 | D17: THURSDAY | G17: AI 4 SUMIT | I17: FRENCH / SKT 4-6 MN / RAJNI | N17: MA 4-5 SHARMILA
C18: 5 | D18: FRIDAY | G18: ARTS 5 LAKSHITA
C19: 6 | D19: SATURDAY | G19: MUSIC/DANCE 6 | N19: H A 6 INCHARGE
B20: VII Lotus | C20: 1 | D20: MONDAY | E20: =E14 -> Attendance / Activity CLASS INCHARGE | F20: S SCI 1-6 SAVITA | G20: MATHS 1-6 PREETI | H20: ENGLISH 1-6 SHAKTI | I20: HINDI 1-6 SARITA | J20: L U N C H | K20: COMM. 1 SONAL | L20: FRENCH / SKT 1-3 MN / RAJNI | M20: SCIENCE 1-6 KUSUM RATHI | N20: LIB 1 KIRTI | O20: SAVITA SV S Sci
C21: 2 | D21: TUESDAY | K21: SPORTS 2-3 JYOTI | N21: MA 2-3 SHARMILA
C22: 3 | D22: WEDNESDAY
C23: 4 | D23: THURSDAY | K23: AI 4 SUMIT | L23: I T 4-6 SANGEETA | N23: MUSIC/DANCE 4
C24: 5 | D24: FRIDAY | K24: COMM. 5-6 SONAL | N24: ARTS 5 LAKSHITA
C25: 6 | D25: SATURDAY | N25: H A 6 INCHARGE
B26: VII Tulip | C26: 1 | D26: MONDAY | E26: =E20 -> Attendance / Activity CLASS INCHARGE | F26: ENGLISH 1-6 SHAKTI | G26: HINDI 1-6 SARITA | H26: I T 1-3 NISHU | I26: SCIENCE 1-6 KUSUM RATHI | J26: L U N C H | K26: AI 1 SUMT | L26: COMM. 1-3 SONAL | M26: MATHS 1-6 PREETI | N26: S S T 1-3 NISHA GILL | O26: SHAKTI SS ENGLISH
C27: 2 | D27: TUESDAY | K27: MUSIC/DANCE 2
C28: 3 | D28: WEDNESDAY | K28: SPORTS 3-4 JYOTI
C29: 4 | D29: THURSDAY | H29: S S T 4-6 NISHA GILL | L29: FRENCH / SKT 4-6 MN / RAJNI | N29: LIBRARY 4 KIRTI
C30: 5 | D30: FRIDAY | K30: ARTS 5 LAKSHITA | N30: MA 5 NISHU
C31: 6 | D31: SATURDAY | K31: MA 6 NISHU | N31: H A 6 INCHARGE
B33: CLASS | C33: PERIOD / WEEKDAYS | E33: ZERO | F33: I | G33: II | H33: III | I33: IV | J33: 0.44791667 | K33: V | L33: VI | M33: VII | N33: VIII | O33: INCHARGE
E34: 07:45 - 08:05 | F34: 08:05 - 08:45 | G34: 08:45 - 09:25 | H34: 09:25 - 10:05 | I34: 10:05 - 10:45 | J34: 0.46180556 | K34: 11:05 - 11:45 | L34: 11:45 - 12:25 | M34: 12:25 - 01:05 | N34: 01:05 - 01:35
C35: DURATION | E35: 08:00 - 08:20 | F35: 08:20 - 09:00 | G35: 09:00 - 09:40 | H35: 09:40 - 10:20 | I35: 10:20 - 11:00 | J35: 0.47222222 | K35: 11:20 - 12:00 | L35: 12:00 - 12:40 | M35: 12:40 - 01:20 | N35: 01:20 - 02:00
E36: 20 Minutes | F36: 40 Minutes | G36: 40 Minutes | H36: 40 Minutes | I36: 40 Minutes | J36: 20Min | K36: 40 Minutes | L36: 40 Minutes | M36: 40 Minutes | N36: 40 Minutes
B38: VIII Rose | C38: 1 | D38: MONDAY | E38: =E26 -> Attendance / Activity CLASS INCHARGE | F38: ENGLISH 1-6 NIDHI | G38: SCIENCE 1-2 KUSUM | H38: LIBRARY 1 KIRTI | I38: MATHS 1-6 PREETI | J38: L U N C H | K38: ARTS 1 LAKSHITA | L38: HINDI 1-6 SARITA | M38: FRENCH / SKT 1-3 MN / RAJNI | N38: S SCIENCE 1-2 SAVITA | O38: NIDHI ND ENGLISH
C39: 2 | D39: TUESDAY | H39: AI 2 SUMIT | K39: COMM. 2-4 SONAL
C40: 3 | D40: WEDNESDAY | G40: SS 3 SAVITA | H40: SCIENCE 3 KUSUM | N40: SCIENCE 3 KUSUM
C41: 4 | D41: THURSDAY | G41: SCIENCE 4-5 KUSUM | H41: I T 4-6 NISHU | M41: MA 4-5 NEELIMA | N41: S SCIENCE 4-5 SAVITA
C42: 5 | D42: FRIDAY | K42: SPORTS 5-6 AATISH
C43: 6 | D43: SATURDAY | G43: SS 6 SAVITA | M43: MUSIC & DANCE 6 | N43: H A 6 INCHARGE
...

Sheet 9-10
B1: INTERNATIONAL BHARTI SCHOOL, 5KM MILESTONE, GOHANA ROAD, ROHTAK
B2: ='7-8'!B2:O2 -> SUMMER TIME TABLE 3.3 (Session 2025-26)
B3: ='7-8'!B3:O3 -> w.e.f - 10.07.2025 (Thursday)
B5: CLASS | C5: PERIOD / DAY/ DURATION | E5: ZERO | F5: I | G5: II | H5: III | I5: IV | J5: 0.45833333 | K5: V | L5: VI | M5: VII | N5: VIII | O5: INCHARGE
E6: 08:00 - 08:20 | F6: 08:20 - 09:00 | G6: 09:00 - 09:40 | H6: 09:40 - 10:20 | I6: 10:20 - 11:00 | J6: 0.47222222 | K6: 11:20 - 12:00 | L6: 12:00 - 12:40 | M6: 12:40 - 01:20 | N6: 01:20 - 02:00
E7: 20 Minutes | F7: 40 Minutes | G7: 40 Minutes | H7: 40 Minutes | I7: 40 Minutes | J7: 20Min | K7: 40 Minutes | L7: 40 Minutes | M7: 40 Minutes | N7: 40 Minutes
B8: IX Rose | C8: 1 | D8: MONDAY | E8: Attendance / Activity CLASS INCHARGE | F8: IT 1-3 NISHU | G8: ENGLISH 1-6 ROOPANSHI | H8: HINDI 1-6 SUNITA HOODA | I8: ECONOMICS 1-2 KUSUM | J8: L U N C H | K8: SOCIAL SCIENCE 1-6 SWEETY | L8: MATHS 1-6 MONIKA LATHER | M8: CHEMISTRY 1-2 SAHIL | N8: BIOLOGY 1-2 RADHIKA | O8: MONIKA LATHER ML MATHS
C9: 2 | D9: TUESDAY
C10: 3 | D10: WEDNESDAY | I10: CHEMISTRY 3-4 SAHIL | M10: ENG 3 ROOPANSHI | N10: MATH 3 MONIKA
C11: 4 | D11: THURSDAY | F11: SPORTS 1-3 AJAY | M11: PHYSICS 4-6 SHARMILA | N11: BIOLOGY 4-5 RADHIKA
C12: 5 | D12: FRIDAY | I12: IT 5 NISHU
C13: 6 | D13: SATURDAY | I13: PHYSICS 6 SHARMILA | N13: H A 6 INCHARGE
B14: IX Lily | C14: 1 | D14: MONDAY | E14: =E8 -> Attendance / Activity CLASS INCHARGE | F14: SPORTS 1-2 AJAY | G14: PHYSICS 1-2 SHARMILA | H14: HINDI 1-6 SUSHIL GILL | I14: SOCIAL SCIENCE 1-4 SWEETY | J14: L U N C H | K14: ENGLISH 1-6 NIDHI | L14: MATHS 1-6 ROBIN | M14: BIOLOGY 1-3 RADHIKA | N14: PHY 1 SHARMILA | O14: SAHIL MALIK SM SCIENCE
C15: 2 | D15: TUESDAY | N15: ECO 2 KUSUM
C16: 3 | D16: WEDNESDAY | F16: CHEMISTRY 3-6 SAHIL MALIK | G16: IT 3-6 REENA | N16: ENG 3 NIDHI
C17: 4 | D17: THURSDAY | M17: SS 4-5 SWEETY | N17: SPORT 4 DEEPAK
C18: 5 | D18: FRIDAY | I18: PHY 5 SHARMILA | N18: ECO 5 KUSUM
C19: 6 | D19: SATURDAY | I19: MATHS 6 ROBIN | M19: BIO 6 RADHIKA | N19: H A 6 INCHARGE
B20: IX Lotus | C20: 1 | D20: MONDAY | E20: =E14 -> Attendance / Activity CLASS INCHARGE | F20: MATHS 1-6 ROBIN | G20: BIOLOGY 1-3 RADHIKA | H20: ECONOMICS 1-2 KUSUM MALIK | I20: GEOGRAPHY 1-6 NEELAM | J20: L U N C H | K20: HINDI 1-6 SUSHIL GILL | L20: ENGLISH 1-6 SHEELA | M20: SPORTS 1-3 AJAY | N20: CHEMISTRY 1-4 SAHIL MALIK | O20: ROBIN RB MATHS
C21: 2 | D21: TUESDAY
C22: 3 | D22: WEDNESDAY | H22: PHYSICS 3-6 SHARMILA
C23: 4 | D23: THURSDAY | G23: I T 4-6 NISHU | M23: MATHS 4 ROBIN
C24: 5 | D24: FRIDAY | M24: BIO 5 RADHIKA | N24: ENG 5 SHEELA
C25: 6 | D25: SATURDAY | M25: IT 6 NISHU | N25: H A 6 INCHARGE
B26: IX Tulip | C26: 1 | D26: MONDAY | E26: =E20 -> Attendance / Activity CLASS INCHARGE | F26: ENGLISH 1-6 SONAL DHILLON | G26: CHEMISTRY 1-4 SAHIL MALIK | H26: PHYSICS 1-2 SHARMILA | I26: HINDI 1-6 SUSHIL GILL | J26: L U N C H | K26: MATHS 1-6 MONIKA LATHER | L26: SOCIAL SCIENCE 1-6 NEELAM | M26: SPORTS 1-3 AJAY | N26: ENG 1 SONAL D | O26: SHARMILA SB SCIENCE
C27: 2 | D27: TUESDAY | N27: MATH 2 MONIKA
C28: 3 | D28: WEDNESDAY | H28: BIOLOGY 3-6 RADHIKA | N28: IT 3-5 REENA
C29: 4 | D29: THURSDAY | M29: ECONOMICS 4-5 KUSUM MALIK
C30: 5 | D30: FRIDAY | G30: PHYSICS 5-6 SHARMILA
C31: 6 | D31: SATURDAY | M31: I T 6 REENA | N31: H A 6 INCHARGE
B33: X Rose | C33: 1 | D33: MONDAY | E33: =E26 -> Attendance / Activity CLASS INCHARGE | F33: HINDI 1-2 SUNITA | G33: ENGLISH 1-6 SHEELA | H33: SS 1-2 SWEETY | I33: SPORTS 1-3 AJAY | J33: L U N C H | K33: I T 1-4 REENA | L33: BIOLOGY 1-2 SAHIL | M33: MATHS 1-2 VIKAS | N33: CHEMISTRY 1-2 TWINKLE | O33: VIKAS VK MATHS
C34: 2 | D34: TUESDAY
C35: 3 | D35: WEDNESDAY | F35: MATHS 3 VIKAS | H35: HISTORY 3-6 NAVJYOTI | L35: PHY 3 SHARMILA | M35: ENG 3 SHEELA | N35: HINDI 3 SUNITA
C36: 4 | D36: THURSDAY | F36: HINDI 4-5 SUNITA | I36: PHY 4 SHARMILA | L36: MATHS 4 VIKAS | M36: MATHS 4-5 VIKAS | N36: CHEMISTRY 4-5 TWINKLE
C37: 5 | D37: FRIDAY | I37: BIOLOGY 5-6 SAHIL | K37: GEO 5-6 NEELAM | L37: PHYSICS 5-6 SHARMILA
C38: 6 | D38: SATURDAY | F38: MATHS 6 VIKAS | M38: HINDI 6 SUNITA | N38: H A 6 ANKUSH
B39: X Lily | C39: 1 | D39: MONDAY | E39: =E33 -> Attendance / Activity CLASS INCHARGE | F39: BIOLOGY 1-2 SAHIL | G39: HISTORY 1-4 NAVJYOTI | H39: CHEMISTRY 1-2 TWINKLE | I39: MATHS 1-6 MONIKA LATHER | J39: L U N C H | K39: HINDI 1-2 SUNITA HOODA | L39: POL SCIENCE 1-2 SWEETY | M39: GEOGRAPHY 1-2 NEELAM | N39: HINDI 1-2 SUNITA HOODA | O39: NAVJYOTI NJ HISTORY
C40: 2 | D40: TUESDAY
C41: 3 | D41: WEDNESDAY | F41: IT 3-6 REENA | H41: ENGLISH 3-6 ROOPANSHI | K41: CHEMISTRY 3-4 TWINKLE | L41: PHYSICS 3-6 MAHESH | M41: MATH 3 MONIKA | N41: ENGLISH 3-5 ROOPANSHI
C42: 4 | D42: THURSDAY | M42: SPORTS 4-6 AATISH
...

Sheet 11-12
B1: INTERNATIONAL BHARTI SCHOOL, 5KM MILESTONE, GOHANA ROAD, ROHTAK
B2: ='9-10'!B2:O2 -> SUMMER TIME TABLE 3.3 (Session 2025-26)
B3: ='9-10'!B3:O3 -> w.e.f - 10.07.2025 (Thursday)
B5: CLASS | C5: PERIOD / DAY/ DURATION | E5: ZERO | F5: I | G5: II | H5: III | I5: IV | J5: 0.45833333 | K5: V | L5: VI | M5: VII | N5: VIII | O5: INCHARGE
E6: 08:00 - 08:20 | F6: 08:20 - 09:00 | G6: 09:00 - 09:40 | H6: 09:40 - 10:20 | I6: 10:20 - 11:00 | J6: 0.47222222 | K6: 11:20 - 12:00 | L6: 12:00 - 12:40 | M6: 12:40 - 01:20 | N6: 01:20 - 02:00
E7: 20 Minutes | F7: 40 Minutes | G7: 40 Minutes | H7: 40 Minutes | I7: 40 Minutes | J7: 20Min | K7: 40 Minutes | L7: 40 Minutes | M7: 40 Minutes | N7: 40 Minutes
B8: XI SCIENCE | C8: 1 | D8: MONDAY | E8: Attendance / Activity CLASS INCHARGE | F8: PHYSICS 1-6 MAHESH | G8: CHEMISTRY 1-2 TWINKLE | H8: MATH/BIO 1-2 VK/DS | I8: MU/PE/FA/IT 1-2 AN/DP/LK/RE | J8: L U N C H | K8: ENGLISH 1-6 SHEELA | O8: SHEELA SE ENGLISH
C9: 2 | D9: TUESDAY
C10: 3 | D10: WEDNESDAY | G10: PHY 3 MAHESH | H10: CHEM 3 TW | I10: CHEM 3 TW | L10: MU/PE 3 | M10: MATH/ BIO 3 VK/DS | N10: MATH/ BIO 3 VK/DS
C11: 4 | D11: THURSDAY | G11: CHEMISTRY 4-5 TWINKLE | H11: MATH/BIO 4-5 VK/DS | I11: MU/PE/FA/IT 4-5 AN/DP/LK/RE
C12: 5 | D12: FRIDAY
C13: 6 | D13: SATURDAY | G13: PHY 6 MAHESH | H13: CHEM 6 TW | I13: CHEM 6 TW | L13: MU/PE/FA/IT 6 | M13: MATH/ BIO 6 VK/DS | N13: MATH/ BIO 6 VK/DS
B14: XI COMMERCE | C14: 1 | D14: MONDAY | E14: =E8 -> Attendance / Activity CLASS INCHARGE | F14: ECONOMICS 1-6 KUSUM | G14: ACCOUNTS 1-6 NEELIMA | H14: B S T 1-6 NEELIMA | I14: MU/PE/FA/IT 1-2 AN/DP/LK/RE | J14: L U N C H | K14: ENGLISH 1-6 ROOPANSHI | O14: ROOPANSHI RP ENGLISH
C15: 2 | D15: TUESDAY
C16: 3 | D16: WEDNESDAY | I16: ECO 3 KUSUM | L16: =L10 -> MU/PE 3 | M16: BST 3 NEELIMA | N16: ECO 3 KUSUM
C17: 4 | D17: THURSDAY | I17: MU/PE/FA/IT 4-5 AN/DP/LK/RE
C18: 5 | D18: FRIDAY
C19: 6 | D19: SATURDAY | I19: ECO 6 KUSUM | L19: MU/PE/FA/IT 6 | M19: ECO 6 KUSUM | N19: ACC. 6 NEELIMA
B20: XI HUMANITIES | C20: 1 | D20: MONDAY | E20: =E14 -> Attendance / Activity CLASS INCHARGE | F20: HISTORY / ECO/ LGL STUDIES 1-6 NAVJYOTI / KUSUM /RADHIKA | G20: POL SCI 1-6 SWEETY | H20: MATHS/ GEOGRAPHY 1-6 VIKAS/ NEELAM | I20: MU/PE/FA/IT/PSY 1-2 AN/DP/LK/RE/JN | J20: L U N C H | K20: ENGLISH 1-6 ROOPANSHI | O20: NEELAM NL GEOGRAPHY
C21: 2 | D21: TUESDAY
C22: 3 | D22: WEDNESDAY | I22: HIS 3 NAVJYOTI | L22: =L10 -> MU/PE 3 | M22: POL SCI 3 SW | N22: LGL 3 RADHIKA
C23: 4 | D23: THURSDAY | I23: MU/PE/FA/IT/PSY 4-5 AN/DP/LK/RE/JN
C24: 5 | D24: FRIDAY
C25: 6 | D25: SATURDAY | I25: HIS 6 NAVJYOTI | L25: MU/PE/FA/IT 6 | M25: POL SCI 6 SW | N25: LGL 6 RADHIKA
B27: CLASS | C27: PERIOD / WEEKDAYS | E27: ZERO | F27: I | G27: II | H27: III | I27: IV | J27: 0.44791667 | K27: V | L27: VI | M27: VII | N27: VIII | O27: INCHARGE
E28: 07:45 - 08:05 | F28: 08:05 - 08:45 | G28: 08:45 - 09:25 | H28: 09:25 - 10:05 | I28: 10:05 - 10:45 | J28: 0.46180556 | K28: 11:05 - 11:45 | L28: 11:45 - 12:25 | M28: 12:25 - 01:05 | N28: 01:05 - 01:35
C29: DURATION | E29: 08:00 - 08:20 | F29: 08:20 - 09:00 | G29: 09:00 - 09:40 | H29: 09:40 - 10:20 | I29: 10:20 - 11:00 | J29: 0.47222222 | K29: 11:20 - 12:00 | L29: 12:00 - 12:40 | M29: 12:40 - 01:20 | N29: 01:20 - 02:00
E30: 20 Minutes | F30: 40 Minutes | G30: 40 Minutes | H30: 40 Minutes | I30: 40 Minutes | J30: 20Min | K30: 40 Minutes | L30: 40 Minutes | M30: 40 Minutes | N30: 40 Minutes
B31: XII SCIENCE | C31: 1 | D31: MONDAY | E31: =E20 -> Attendance / Activity CLASS INCHARGE | F31: CHEMISTRY 1-6 TWINKLE | G31: PHYSICS 1-2 MAHESH | H31: MU/PE/FA/IT 1-2 AN/DP/LK/RE | I31: ENGLISH 1-2 SHEELA | J31: L U N C H | K31: MATHS/ BIOLOGY 1-6 VIKAS/ DEEPSHIKHA | O31: TWINKLE TW CHEMISTRY
C32: 2 | D32: TUESDAY
C33: 3 | D33: WEDNESDAY | G33: CHEM 3 TW | H33: PHY 3 MAHESH | I33: PHY 3 MAHESH | L33: MATH/ BIO 3 VK/DS | M33: MU/PE 3 | N33: ENGLISH 3 SHEELA
C34: 4 | D34: THURSDAY | G34: PHYSICS 4-5 MAHESH | H34: MU/PE/FA/IT 4-5 AN/DP/LK/RE | I34: ENGLISH 4-5 SHEELA
C35: 5 | D35: FRIDAY
C36: 6 | D36: SATURDAY | G36: CHEM 6 TW | H36: PHY 6 MAHESH | I36: PHY 6 MAHESH | L36: MATH/ BIO 3 VK/DS | M36: MU/PE 6 | N36: ENGLISH 6 SHEELA
B37: XII COMMERCE | C37: 1 | D37: MONDAY | E37: =E31 -> Attendance / Activity CLASS INCHARGE | F37: ACCOUNTS 1-6 NEELIMA | G37: ECONOMICS 1-6 KUSUM | H37: MUSIC / PHY EDU/ FINE ARTS/ IT 1-6 ANKUSH / DEEPAK/ LAKSHITA / REENA | I37: ENGLISH 1-6 ROOPANSHI | J37: L U N C H | K37: B S T 1-6 NEELIMA | O37: NEELIMA NM BST & ACC
C38: 2 | D38: TUESDAY
C39: 3 | D39: WEDNESDAY | L39: LIB. 3 KIRTI | M39: ECO 3 KUSUM | N39: ACC 3 NEELIMA
C40: 4 | D40: THURSDAY
C41: 5 | D41: FRIDAY
C42: 6 | D42: SATURDAY | L42: LIB. 6 KIRTI | M42: ACC 6 NEELIMA | N42: ECO 6 KUSUM
...
